[02/10/2023 09:03:41 AM][INFO][werkzeug]_internal.py[224]:_log() -> [31m[1mWARNING: This is a development server. Do not use it in a production deployment. Use a production WSGI server instead.[0m
 * Running on all addresses (0.0.0.0)
 * Running on http://127.0.0.1:5007
 * Running on http://192.168.50.108:5007
[02/10/2023 09:03:41 AM][INFO][werkzeug]_internal.py[224]:_log() -> [33mPress CTRL+C to quit[0m
[02/10/2023 09:03:58 AM][INFO][werkzeug]_internal.py[224]:_log() -> 127.0.0.1 - - [10/Feb/2023 09:03:58] "[32mGET / HTTP/1.1[0m" 302 -
[02/10/2023 09:03:59 AM][INFO][werkzeug]_internal.py[224]:_log() -> 127.0.0.1 - - [10/Feb/2023 09:03:59] "GET /login HTTP/1.1" 200 -
[02/10/2023 09:03:59 AM][INFO][werkzeug]_internal.py[224]:_log() -> 127.0.0.1 - - [10/Feb/2023 09:03:59] "[33mGET /favicon.ico HTTP/1.1[0m" 404 -
[02/10/2023 09:16:19 AM][INFO][werkzeug]_internal.py[224]:_log() -> [31m[1mWARNING: This is a development server. Do not use it in a production deployment. Use a production WSGI server instead.[0m
 * Running on all addresses (0.0.0.0)
 * Running on http://127.0.0.1:5007
 * Running on http://192.168.50.108:5007
[02/10/2023 09:16:19 AM][INFO][werkzeug]_internal.py[224]:_log() -> [33mPress CTRL+C to quit[0m
[02/10/2023 09:16:31 AM][INFO][werkzeug]_internal.py[224]:_log() -> 127.0.0.1 - - [10/Feb/2023 09:16:31] "[32mGET / HTTP/1.1[0m" 302 -
[02/10/2023 09:16:31 AM][INFO][werkzeug]_internal.py[224]:_log() -> 127.0.0.1 - - [10/Feb/2023 09:16:31] "GET /login HTTP/1.1" 200 -
[02/10/2023 09:16:31 AM][INFO][werkzeug]_internal.py[224]:_log() -> 127.0.0.1 - - [10/Feb/2023 09:16:31] "[33mGET /favicon.ico HTTP/1.1[0m" 404 -
[02/10/2023 09:20:22 AM][INFO][werkzeug]_internal.py[224]:_log() -> 127.0.0.1 - - [10/Feb/2023 09:20:22] "[32mGET / HTTP/1.1[0m" 302 -
[02/10/2023 09:20:22 AM][INFO][werkzeug]_internal.py[224]:_log() -> 127.0.0.1 - - [10/Feb/2023 09:20:22] "GET /login HTTP/1.1" 200 -
[02/10/2023 09:20:42 AM][INFO][werkzeug]_internal.py[224]:_log() -> [31m[1mWARNING: This is a development server. Do not use it in a production deployment. Use a production WSGI server instead.[0m
 * Running on all addresses (0.0.0.0)
 * Running on http://127.0.0.1:5007
 * Running on http://192.168.50.108:5007
[02/10/2023 09:20:42 AM][INFO][werkzeug]_internal.py[224]:_log() -> [33mPress CTRL+C to quit[0m
[02/10/2023 09:20:53 AM][INFO][werkzeug]_internal.py[224]:_log() -> 127.0.0.1 - - [10/Feb/2023 09:20:53] "GET /register HTTP/1.1" 200 -
[02/10/2023 09:21:45 AM][ERROR][server]app.py[1741]:log_exception() -> Exception on /register [POST]
Traceback (most recent call last):
  File "C:\Users\H\Documents\auto7shifts\venv\Lib\site-packages\sqlalchemy\engine\base.py", line 1900, in _execute_context
    self.dialect.do_execute(
  File "C:\Users\H\Documents\auto7shifts\venv\Lib\site-packages\sqlalchemy\engine\default.py", line 736, in do_execute
    cursor.execute(statement, parameters)
sqlite3.OperationalError: no such table: user

The above exception was the direct cause of the following exception:

Traceback (most recent call last):
  File "C:\Users\H\Documents\auto7shifts\venv\Lib\site-packages\flask\app.py", line 2525, in wsgi_app
    response = self.full_dispatch_request()
               ^^^^^^^^^^^^^^^^^^^^^^^^^^^^
  File "C:\Users\H\Documents\auto7shifts\venv\Lib\site-packages\flask\app.py", line 1822, in full_dispatch_request
    rv = self.handle_user_exception(e)
         ^^^^^^^^^^^^^^^^^^^^^^^^^^^^^
  File "C:\Users\H\Documents\auto7shifts\venv\Lib\site-packages\flask\app.py", line 1820, in full_dispatch_request
    rv = self.dispatch_request()
         ^^^^^^^^^^^^^^^^^^^^^^^
  File "C:\Users\H\Documents\auto7shifts\venv\Lib\site-packages\flask\app.py", line 1796, in dispatch_request
    return self.ensure_sync(self.view_functions[rule.endpoint])(**view_args)
           ^^^^^^^^^^^^^^^^^^^^^^^^^^^^^^^^^^^^^^^^^^^^^^^^^^^^^^^^^^^^^^^^^
  File "C:\Users\H\Documents\auto7shifts\v3\server.py", line 123, in register
    db.session.commit()
  File "<string>", line 2, in commit
  File "C:\Users\H\Documents\auto7shifts\venv\Lib\site-packages\sqlalchemy\orm\session.py", line 1451, in commit
    self._transaction.commit(_to_root=self.future)
  File "C:\Users\H\Documents\auto7shifts\venv\Lib\site-packages\sqlalchemy\orm\session.py", line 829, in commit
    self._prepare_impl()
  File "C:\Users\H\Documents\auto7shifts\venv\Lib\site-packages\sqlalchemy\orm\session.py", line 808, in _prepare_impl
    self.session.flush()
  File "C:\Users\H\Documents\auto7shifts\venv\Lib\site-packages\sqlalchemy\orm\session.py", line 3444, in flush
    self._flush(objects)
  File "C:\Users\H\Documents\auto7shifts\venv\Lib\site-packages\sqlalchemy\orm\session.py", line 3583, in _flush
    with util.safe_reraise():
  File "C:\Users\H\Documents\auto7shifts\venv\Lib\site-packages\sqlalchemy\util\langhelpers.py", line 70, in __exit__
    compat.raise_(
  File "C:\Users\H\Documents\auto7shifts\venv\Lib\site-packages\sqlalchemy\util\compat.py", line 211, in raise_
    raise exception
  File "C:\Users\H\Documents\auto7shifts\venv\Lib\site-packages\sqlalchemy\orm\session.py", line 3544, in _flush
    flush_context.execute()
  File "C:\Users\H\Documents\auto7shifts\venv\Lib\site-packages\sqlalchemy\orm\unitofwork.py", line 456, in execute
    rec.execute(self)
  File "C:\Users\H\Documents\auto7shifts\venv\Lib\site-packages\sqlalchemy\orm\unitofwork.py", line 630, in execute
    util.preloaded.orm_persistence.save_obj(
  File "C:\Users\H\Documents\auto7shifts\venv\Lib\site-packages\sqlalchemy\orm\persistence.py", line 245, in save_obj
    _emit_insert_statements(
  File "C:\Users\H\Documents\auto7shifts\venv\Lib\site-packages\sqlalchemy\orm\persistence.py", line 1238, in _emit_insert_statements
    result = connection._execute_20(
             ^^^^^^^^^^^^^^^^^^^^^^^
  File "C:\Users\H\Documents\auto7shifts\venv\Lib\site-packages\sqlalchemy\engine\base.py", line 1705, in _execute_20
    return meth(self, args_10style, kwargs_10style, execution_options)
           ^^^^^^^^^^^^^^^^^^^^^^^^^^^^^^^^^^^^^^^^^^^^^^^^^^^^^^^^^^^
  File "C:\Users\H\Documents\auto7shifts\venv\Lib\site-packages\sqlalchemy\sql\elements.py", line 334, in _execute_on_connection
    return connection._execute_clauseelement(
           ^^^^^^^^^^^^^^^^^^^^^^^^^^^^^^^^^^
  File "C:\Users\H\Documents\auto7shifts\venv\Lib\site-packages\sqlalchemy\engine\base.py", line 1572, in _execute_clauseelement
    ret = self._execute_context(
          ^^^^^^^^^^^^^^^^^^^^^^
  File "C:\Users\H\Documents\auto7shifts\venv\Lib\site-packages\sqlalchemy\engine\base.py", line 1943, in _execute_context
    self._handle_dbapi_exception(
  File "C:\Users\H\Documents\auto7shifts\venv\Lib\site-packages\sqlalchemy\engine\base.py", line 2124, in _handle_dbapi_exception
    util.raise_(
  File "C:\Users\H\Documents\auto7shifts\venv\Lib\site-packages\sqlalchemy\util\compat.py", line 211, in raise_
    raise exception
  File "C:\Users\H\Documents\auto7shifts\venv\Lib\site-packages\sqlalchemy\engine\base.py", line 1900, in _execute_context
    self.dialect.do_execute(
  File "C:\Users\H\Documents\auto7shifts\venv\Lib\site-packages\sqlalchemy\engine\default.py", line 736, in do_execute
    cursor.execute(statement, parameters)
sqlalchemy.exc.OperationalError: (sqlite3.OperationalError) no such table: user
[SQL: INSERT INTO user (username, password) VALUES (?, ?)]
[parameters: ('charleshparmley@icloud.com', 'Earthday19!@22')]
(Background on this error at: https://sqlalche.me/e/14/e3q8)
[02/10/2023 09:21:45 AM][INFO][werkzeug]_internal.py[224]:_log() -> 127.0.0.1 - - [10/Feb/2023 09:21:45] "[35m[1mPOST /register HTTP/1.1[0m" 500 -
[02/10/2023 09:22:27 AM][INFO][werkzeug]_internal.py[224]:_log() -> [31m[1mWARNING: This is a development server. Do not use it in a production deployment. Use a production WSGI server instead.[0m
 * Running on all addresses (0.0.0.0)
 * Running on http://127.0.0.1:5007
 * Running on http://192.168.50.108:5007
[02/10/2023 09:22:27 AM][INFO][werkzeug]_internal.py[224]:_log() -> [33mPress CTRL+C to quit[0m
[02/10/2023 09:22:52 AM][ERROR][server]app.py[1741]:log_exception() -> Exception on /register [POST]
Traceback (most recent call last):
  File "C:\Users\H\Documents\auto7shifts\venv\Lib\site-packages\sqlalchemy\engine\base.py", line 1900, in _execute_context
    self.dialect.do_execute(
  File "C:\Users\H\Documents\auto7shifts\venv\Lib\site-packages\sqlalchemy\engine\default.py", line 736, in do_execute
    cursor.execute(statement, parameters)
sqlite3.OperationalError: no such table: user

The above exception was the direct cause of the following exception:

Traceback (most recent call last):
  File "C:\Users\H\Documents\auto7shifts\venv\Lib\site-packages\flask\app.py", line 2525, in wsgi_app
    response = self.full_dispatch_request()
               ^^^^^^^^^^^^^^^^^^^^^^^^^^^^
  File "C:\Users\H\Documents\auto7shifts\venv\Lib\site-packages\flask\app.py", line 1822, in full_dispatch_request
    rv = self.handle_user_exception(e)
         ^^^^^^^^^^^^^^^^^^^^^^^^^^^^^
  File "C:\Users\H\Documents\auto7shifts\venv\Lib\site-packages\flask\app.py", line 1820, in full_dispatch_request
    rv = self.dispatch_request()
         ^^^^^^^^^^^^^^^^^^^^^^^
  File "C:\Users\H\Documents\auto7shifts\venv\Lib\site-packages\flask\app.py", line 1796, in dispatch_request
    return self.ensure_sync(self.view_functions[rule.endpoint])(**view_args)
           ^^^^^^^^^^^^^^^^^^^^^^^^^^^^^^^^^^^^^^^^^^^^^^^^^^^^^^^^^^^^^^^^^
  File "C:\Users\H\Documents\auto7shifts\v3\server.py", line 123, in register
    db.session.commit()
  File "<string>", line 2, in commit
  File "C:\Users\H\Documents\auto7shifts\venv\Lib\site-packages\sqlalchemy\orm\session.py", line 1451, in commit
    self._transaction.commit(_to_root=self.future)
  File "C:\Users\H\Documents\auto7shifts\venv\Lib\site-packages\sqlalchemy\orm\session.py", line 829, in commit
    self._prepare_impl()
  File "C:\Users\H\Documents\auto7shifts\venv\Lib\site-packages\sqlalchemy\orm\session.py", line 808, in _prepare_impl
    self.session.flush()
  File "C:\Users\H\Documents\auto7shifts\venv\Lib\site-packages\sqlalchemy\orm\session.py", line 3444, in flush
    self._flush(objects)
  File "C:\Users\H\Documents\auto7shifts\venv\Lib\site-packages\sqlalchemy\orm\session.py", line 3583, in _flush
    with util.safe_reraise():
  File "C:\Users\H\Documents\auto7shifts\venv\Lib\site-packages\sqlalchemy\util\langhelpers.py", line 70, in __exit__
    compat.raise_(
  File "C:\Users\H\Documents\auto7shifts\venv\Lib\site-packages\sqlalchemy\util\compat.py", line 211, in raise_
    raise exception
  File "C:\Users\H\Documents\auto7shifts\venv\Lib\site-packages\sqlalchemy\orm\session.py", line 3544, in _flush
    flush_context.execute()
  File "C:\Users\H\Documents\auto7shifts\venv\Lib\site-packages\sqlalchemy\orm\unitofwork.py", line 456, in execute
    rec.execute(self)
  File "C:\Users\H\Documents\auto7shifts\venv\Lib\site-packages\sqlalchemy\orm\unitofwork.py", line 630, in execute
    util.preloaded.orm_persistence.save_obj(
  File "C:\Users\H\Documents\auto7shifts\venv\Lib\site-packages\sqlalchemy\orm\persistence.py", line 245, in save_obj
    _emit_insert_statements(
  File "C:\Users\H\Documents\auto7shifts\venv\Lib\site-packages\sqlalchemy\orm\persistence.py", line 1238, in _emit_insert_statements
    result = connection._execute_20(
             ^^^^^^^^^^^^^^^^^^^^^^^
  File "C:\Users\H\Documents\auto7shifts\venv\Lib\site-packages\sqlalchemy\engine\base.py", line 1705, in _execute_20
    return meth(self, args_10style, kwargs_10style, execution_options)
           ^^^^^^^^^^^^^^^^^^^^^^^^^^^^^^^^^^^^^^^^^^^^^^^^^^^^^^^^^^^
  File "C:\Users\H\Documents\auto7shifts\venv\Lib\site-packages\sqlalchemy\sql\elements.py", line 334, in _execute_on_connection
    return connection._execute_clauseelement(
           ^^^^^^^^^^^^^^^^^^^^^^^^^^^^^^^^^^
  File "C:\Users\H\Documents\auto7shifts\venv\Lib\site-packages\sqlalchemy\engine\base.py", line 1572, in _execute_clauseelement
    ret = self._execute_context(
          ^^^^^^^^^^^^^^^^^^^^^^
  File "C:\Users\H\Documents\auto7shifts\venv\Lib\site-packages\sqlalchemy\engine\base.py", line 1943, in _execute_context
    self._handle_dbapi_exception(
  File "C:\Users\H\Documents\auto7shifts\venv\Lib\site-packages\sqlalchemy\engine\base.py", line 2124, in _handle_dbapi_exception
    util.raise_(
  File "C:\Users\H\Documents\auto7shifts\venv\Lib\site-packages\sqlalchemy\util\compat.py", line 211, in raise_
    raise exception
  File "C:\Users\H\Documents\auto7shifts\venv\Lib\site-packages\sqlalchemy\engine\base.py", line 1900, in _execute_context
    self.dialect.do_execute(
  File "C:\Users\H\Documents\auto7shifts\venv\Lib\site-packages\sqlalchemy\engine\default.py", line 736, in do_execute
    cursor.execute(statement, parameters)
sqlalchemy.exc.OperationalError: (sqlite3.OperationalError) no such table: user
[SQL: INSERT INTO user (username, password) VALUES (?, ?)]
[parameters: ('charleshparmley@icloud.com', 'Earthday19!@22')]
(Background on this error at: https://sqlalche.me/e/14/e3q8)
[02/10/2023 09:22:52 AM][INFO][werkzeug]_internal.py[224]:_log() -> 127.0.0.1 - - [10/Feb/2023 09:22:52] "[35m[1mPOST /register HTTP/1.1[0m" 500 -
